Workbook

Sheet Resumen Curso
A1: Planificación curso de IA aplicada - Cinecta
A2: Duración total | B2: 12 horas | C2: Formato | D2: 8 clases x 1,5 horas | E2: Modalidad | F2: Taller práctico sincrónico
A3: Empresa | B3: Cinecta | C3: Enfoque | D3: Productividad, finanzas, datos, documentos, agentes y automatización | E3: Versión | F3: Actualizada 2026
A4: Fuente base | B4: Presentación de clases anterior adjunta: Inteligencia Artificial Generativa para Equipos de Trabajo - CONECTA
A6: KPI | B6: Valor | C6: Detalle
A7: Total clases | B7: =COUNTA(B18:B25) -> 7 | C7: Clases planificadas
A8: Total horas | B8: =SUM('Planificación 8 Clases'!H:H)/60 -> 12 | C8: Debe ser 12
A9: Minutos de práctica alumnos | B9: =SUMIF('Planificación 8 Clases'!E:E,"Ejercicio - práctica alumnos",'Planificación 8 Clases'!H:H)+SUMIF('Planificación 8 Clases'!E:E,"Trabajo en grupo",'Planificación 8 Clases'!H:H) -> 205 | C9: Práctica directa + trabajo guiado
A10: N° ejercicios prácticos | B10: =COUNTA('Matriz Ejercicios'!B:B)-1 -> 17 | C10: Incluye ejercicios codificados
A12: Requerimiento Cinecta | B12: Clase donde se incorpora | C12: Ejercicio / actividad | D12: Estado | E12: Observación
A13: Contraste de bases de contratos y normas con foco Finanzas | B13: Clase 4 | C13: Ejercicio 4.2 | D13: Incluido | E13: NotebookLM + tabla de cumplimiento, riesgo y recomendación
A14: Automatización avanzada de correos y presentaciones | B14: Clases 4, 5 y 6 | C14: Ejercicios 4.3, 5.1 y 6.1 | D14: Incluido | E14: De minuta a presentación, correo y flujo automatizado
A15: Revisión de bases de licitación mediante agentes | B15: Clase 6 | C15: Ejercicio 6.2 | D15: Incluido | E15: Checklist de documentos, requisitos y riesgos
A16: Análisis de datos e indicadores por departamento | B16: Clase 3 | C16: Ejercicio 3.2 | D16: Incluido | E16: Calidad, Oficina Técnica, Planificación y RR.HH.
A17: Gestión automática de reuniones y compromisos | B17: Clases 2 y 5 | C17: Ejercicios 2.1 y 5.1 | D17: Incluido | E17: Minuta, compromisos y correos
A18: Exploración de conexiones a sistemas internos (MCP) | B18: Clase 6 | C18: Ejercicio 6.3 | D18: Incluido como demo conceptual | E18: Depende de permisos y acceso a ERP/sistemas internos
A20: Clase | B20: Tema | C20: Horas | D20: Minutos | E20: Barra visual | F20: Foco de aprendizaje
A21: 1 | B21: Inicio estratégico y demostraciones | C21: =D21/60 -> 1.5 | D21: =SUMIF('Planificación 8 Clases'!$A:$A,A21,'Planificación 8 Clases'!$H:$H) -> 90 | E21: =REPT("█",ROUND(C21*6,0)) -> █████████ | F21: Alinear expectativas y mostrar potencial
A22: 2 | B22: Prompt básico y ROCEF | C22: =D22/60 -> 1.5 | D22: =SUMIF('Planificación 8 Clases'!$A:$A,A22,'Planificación 8 Clases'!$H:$H) -> 90 | E22: =REPT("█",ROUND(C22*6,0)) -> █████████ | F22: Crear prompts operativos
A23: 3 | B23: Prompt para análisis de datos | C23: =D23/60 -> 1.5 | D23: =SUMIF('Planificación 8 Clases'!$A:$A,A23,'Planificación 8 Clases'!$H:$H) -> 90 | E23: =REPT("█",ROUND(C23*6,0)) -> █████████ | F23: Transformar datos en decisiones
A24: 4 | B24: Herramientas IA | C24: =D24/60 -> 1.5 | D24: =SUMIF('Planificación 8 Clases'!$A:$A,A24,'Planificación 8 Clases'!$H:$H) -> 90 | E24: =REPT("█",ROUND(C24*6,0)) -> █████████ | F24: Elegir y combinar herramientas
A25: 5 | B25: Automatización básica | C25: =D25/60 -> 1.5 | D25: =SUMIF('Planificación 8 Clases'!$A:$A,A25,'Planificación 8 Clases'!$H:$H) -> 90 | E25: =REPT("█",ROUND(C25*6,0)) -> █████████ | F25: Crear asistentes y flujos básicos
A26: 6 | B26: Automatización avanzada | C26: =D26/60 -> 1.5 | D26: =SUMIF('Planificación 8 Clases'!$A:$A,A26,'Planificación 8 Clases'!$H:$H) -> 90 | E26: =REPT("█",ROUND(C26*6,0)) -> █████████ | F26: Diseñar automatizaciones avanzadas
A27: 7 | B27: Proyecto aplicado | C27: =D27/60 -> 1.5 | D27: =SUMIF('Planificación 8 Clases'!$A:$A,A27,'Planificación 8 Clases'!$H:$H) -> 90 | E27: =REPT("█",ROUND(C27*6,0)) -> █████████ | F27: Convertir ideas en proyectos aplicables
A28: 8 | B28: Presentaciones finales | C28: =D28/60 -> 1.5 | D28: =SUMIF('Planificación 8 Clases'!$A:$A,A28,'Planificación 8 Clases'!$H:$H) -> 90 | E28: =REPT("█",ROUND(C28*6,0)) -> █████████ | F28: Comunicar y evaluar soluciones
A30: Nota de uso | B30: La planificación asume bloques de 90 minutos. En los ejercicios, la práctica de alumnos dura 10 minutos como regla base.

Sheet Planificación 8 Clases
A1: Clase | B1: Nombre clase | C1: Ejercicio | D1: Actividad / título | E1: Tipo | F1: Inicio | G1: Término | H1: Duración min | I1: Herramientas
A2: 1 | B2: Inicio estratégico y demostraciones | D2: Inicio y presentación: contexto del curso, objetivos, expectativas y reglas de trabajo | E2: Inicio | F2: 00:00 | G2: 00:20 | H2: 20
A3: 1 | B3: Inicio estratégico y demostraciones | D3: Teoría aplicada: IA generativa, LLMs, ventana de contexto, riesgos y oportunidades | E3: Teoría | F3: 00:20 | G3: 00:40 | H3: 20
A4: 1 | B4: Inicio estratégico y demostraciones | D4: Demostración 1: De reunión a ejecución, en minutos | E4: Demostración | F4: 00:40 | G4: 00:55 | H4: 15 | I4: ChatGPT
A5: 1 | B5: Inicio estratégico y demostraciones | D5: Demostración 2: De Excel a dashboard ejecutivo | E5: Demostración | F5: 00:55 | G5: 01:10 | H5: 15 | I5: Claude
A6: 1 | B6: Inicio estratégico y demostraciones | D6: Demostración 3: Presentaciones en NotebookLM, Claude Design y Codex como cadena de trabajo | E6: Demostración | F6: 01:10 | G6: 01:25 | H6: 15 | I6: NotebookLM / Gamma / Claude Design / Codex
A7: 1 | B7: Inicio estratégico y demostraciones | D7: Cierre y preguntas | E7: Preguntas de Alumnos | F7: 01:25 | G7: 01:30 | H7: 5
A8: 2 | B8: Prompt básico y metodología ROCEF | D8: Apertura: objetivos de la clase y regla de trabajo con prompts | E8: Inicio | F8: 00:00 | G8: 00:05 | H8: 5 | I8: ChatGPT / Claude
A9: 2 | B9: Prompt básico y metodología ROCEF | C9: 2.1 | D9: Ejercicio 2.1: explicación del resultado esperado — De reunión a ejecución, en minutos | E9: Ejercicio - explicación | F9: 00:05 | G9: 00:15 | H9: 10 | I9: ChatGPT
A10: 2 | B10: Prompt básico y metodología ROCEF | C10: 2.1 | D10: Ejercicio 2.1: demostración del profesor — De reunión a ejecución, en minutos | E10: Ejercicio - demo profesor | F10: 00:15 | G10: 00:20 | H10: 5 | I10: ChatGPT
A11: 2 | B11: Prompt básico y metodología ROCEF | C11: 2.1 | D11: Ejercicio 2.1: práctica de alumnos — De reunión a ejecución, en minutos | E11: Ejercicio - práctica alumnos | F11: 00:20 | G11: 00:30 | H11: 10 | I11: ChatGPT
A12: 2 | B12: Prompt básico y metodología ROCEF | C12: 2.2 | D12: Ejercicio 2.2: explicación del resultado esperado — Control inteligente de facturas | E12: Ejercicio - explicación | F12: 00:30 | G12: 00:40 | H12: 10 | I12: ChatGPT
A13: 2 | B13: Prompt básico y metodología ROCEF | C13: 2.2 | D13: Ejercicio 2.2: demostración del profesor — Control inteligente de facturas | E13: Ejercicio - demo profesor | F13: 00:40 | G13: 00:45 | H13: 5 | I13: ChatGPT
A14: 2 | B14: Prompt básico y metodología ROCEF | C14: 2.2 | D14: Ejercicio 2.2: práctica de alumnos — Control inteligente de facturas | E14: Ejercicio - práctica alumnos | F14: 00:45 | G14: 00:55 | H14: 10 | I14: ChatGPT
A15: 2 | B15: Prompt básico y metodología ROCEF | C15: 2.3 | D15: Ejercicio 2.3: explicación del resultado esperado — De Excel a dashboard ejecutivo | E15: Ejercicio - explicación | F15: 00:55 | G15: 01:05 | H15: 10 | I15: Claude
A16: 2 | B16: Prompt básico y metodología ROCEF | C16: 2.3 | D16: Ejercicio 2.3: demostración del profesor —De Excel a dashboard ejecutivo | E16: Ejercicio - demo profesor | F16: 01:05 | G16: 01:10 | H16: 5 | I16: Claude
A17: 2 | B17: Prompt básico y metodología ROCEF | C17: 2.3 | D17: Ejercicio 2.3: práctica de alumnos — De Excel a dashboard ejecutivo | E17: Ejercicio - práctica alumnos | F17: 01:10 | G17: 01:20 | H17: 10 | I17: Claude
A18: 2 | B18: Prompt básico y metodología ROCEF | D18: Resolver Dudas | E18: Preguntas de Alumnos | F18: 01:20 | G18: 01:30 | H18: 10
A19: 3 | B19: Prompt aplicado a análisis de datos | D19: Microteoría: cómo pedir análisis de datos, validar resultados y evitar conclusiones falsas | E19: Teoría | F19: 00:00 | G19: 00:10 | H19: 10 | I19: ChatGPT con análisis de datos / Excel
A20: 3 | B20: Prompt aplicado a análisis de datos | C20: 3.1 | D20: Ejercicio 3.1: explicación del resultado esperado — Análisis de prospección comercial: tasa de apertura por segmento y recomendación | E20: Ejercicio - explicación | F20: 00:10 | G20: 00:15 | H20: 5 | I20: ChatGPT con Excel/CSV
A21: 3 | B21: Prompt aplicado a análisis de datos | C21: 3.1 | D21: Ejercicio 3.1: demostración del profesor — Análisis de prospección comercial: tasa de apertura por segmento y recomendación | E21: Ejercicio - demo profesor | F21: 00:15 | G21: 00:25 | H21: 10 | I21: ChatGPT con Excel/CSV
A22: 3 | B22: Prompt aplicado a análisis de datos | C22: 3.1 | D22: Ejercicio 3.1: práctica de alumnos — Análisis de prospección comercial: tasa de apertura por segmento y recomendación | E22: Ejercicio - práctica alumnos | F22: 00:25 | G22: 00:35 | H22: 10 | I22: ChatGPT con Excel/CSV
A23: 3 | B23: Prompt aplicado a análisis de datos | C23: 3.2 | D23: Ejercicio 3.2: explicación del resultado esperado — Indicadores por departamento: Calidad, Oficina Técnica, Planificación y RR.HH. | E23: Ejercicio - explicación | F23: 00:35 | G23: 00:40 | H23: 5 | I23: ChatGPT / Claude + Excel
A24: 3 | B24: Prompt aplicado a análisis de datos | C24: 3.2 | D24: Ejercicio 3.2: demostración del profesor — Indicadores por departamento: Calidad, Oficina Técnica, Planificación y RR.HH. | E24: Ejercicio - demo profesor | F24: 00:40 | G24: 00:50 | H24: 10 | I24: ChatGPT / Claude + Excel
A25: 3 | B25: Prompt aplicado a análisis de datos | C25: 3.2 | D25: Ejercicio 3.2: práctica de alumnos — Indicadores por departamento: Calidad, Oficina Técnica, Planificación y RR.HH. | E25: Ejercicio - práctica alumnos | F25: 00:50 | G25: 01:00 | H25: 10 | I25: ChatGPT / Claude + Excel
A26: 3 | B26: Prompt aplicado a análisis de datos | C26: 3.3 | D26: Ejercicio 3.3: explicación del resultado esperado — Auditoría de planilla: duplicados, outliers, inconsistencias y resumen ejecutivo | E26: Ejercicio - explicación | F26: 01:00 | G26: 01:05 | H26: 5 | I26: ChatGPT / Excel
A27: 3 | B27: Prompt aplicado a análisis de datos | C27: 3.3 | D27: Ejercicio 3.3: demostración del profesor — Auditoría de planilla: duplicados, outliers, inconsistencias y resumen ejecutivo | E27: Ejercicio - demo profesor | F27: 01:05 | G27: 01:15 | H27: 10 | I27: ChatGPT / Excel
A28: 3 | B28: Prompt aplicado a análisis de datos | C28: 3.3 | D28: Ejercicio 3.3: práctica de alumnos — Auditoría de planilla: duplicados, outliers, inconsistencias y resumen ejecutivo | E28: Ejercicio - práctica alumnos | F28: 01:15 | G28: 01:25 | H28: 10 | I28: ChatGPT / Excel
A29: 3 | B29: Prompt aplicado a análisis de datos | D29: Cierre: checklist para validar análisis antes de enviarlo a una jefatura | E29: Cierre | F29: 01:25 | G29: 01:30 | H29: 5 | I29: Checklist
A30: 4 | B30: Herramientas IA: NotebookLM, Claude Design, Gamma y Codex | D30: Apertura: mapa de herramientas y criterio de selección según tarea | E30: Inicio | F30: 00:00 | G30: 00:08 | H30: 8 | I30: NotebookLM / Gamma / Claude Design / Codex
A31: 4 | B31: Herramientas IA: NotebookLM, Claude Design, Gamma y Codex | C31: 4.1 | D31: Ejercicio 4.1: explicación del resultado esperado — NotebookLM: resumir procedimiento interno y responder preguntas con base documental | E31: Ejercicio - explicación | F31: 00:08 | G31: 00:11 | H31: 3 | I31: NotebookLM
A32: 4 | B32: Herramientas IA: NotebookLM, Claude Design, Gamma y Codex | C32: 4.1 | D32: Ejercicio 4.1: demostración del profesor — NotebookLM: resumir procedimiento interno y responder preguntas con base documental | E32: Ejercicio - demo profesor | F32: 00:11 | G32: 00:16 | H32: 5 | I32: NotebookLM
A33: 4 | B33: Herramientas IA: NotebookLM, Claude Design, Gamma y Codex | C33: 4.1 | D33: Ejercicio 4.1: práctica de alumnos — NotebookLM: resumir procedimiento interno y responder preguntas con base documental | E33: Ejercicio - práctica alumnos | F33: 00:16 | G33: 00:26 | H33: 10 | I33: NotebookLM
A34: 4 | B34: Herramientas IA: NotebookLM, Claude Design, Gamma y Codex | C34: 4.2 | D34: Ejercicio 4.2: explicación del resultado esperado — Contraste de bases de contrato vs normativa interna con enfoque financiero | E34: Ejercicio - explicación | F34: 00:26 | G34: 00:29 | H34: 3 | I34: NotebookLM / ChatGPT
A35: 4 | B35: Herramientas IA: NotebookLM, Claude Design, Gamma y Codex | C35: 4.2 | D35: Ejercicio 4.2: demostración del profesor — Contraste de bases de contrato vs normativa interna con enfoque financiero | E35: Ejercicio - demo profesor | F35: 00:29 | G35: 00:34 | H35: 5 | I35: NotebookLM / ChatGPT
A36: 4 | B36: Herramientas IA: NotebookLM, Claude Design, Gamma y Codex | C36: 4.2 | D36: Ejercicio 4.2: práctica de alumnos — Contraste de bases de contrato vs normativa interna con enfoque financiero | E36: Ejercicio - práctica alumnos | F36: 00:34 | G36: 00:44 | H36: 10 | I36: NotebookLM / ChatGPT
A37: 4 | B37: Herramientas IA: NotebookLM, Claude Design, Gamma y Codex | C37: 4.3 | D37: Ejercicio 4.3: explicación del resultado esperado — Presentación rápida desde minuta: estructura para Gamma y mejora visual con Claude Design | E37: Ejercicio - explicación | F37: 00:44 | G37: 00:47 | H37: 3 | I37: Gamma / Claude Design
A38: 4 | B38: Herramientas IA: NotebookLM, Claude Design, Gamma y Codex | C38: 4.3 | D38: Ejercicio 4.3: demostración del profesor — Presentación rápida desde minuta: estructura para Gamma y mejora visual con Claude Design | E38: Ejercicio - demo profesor | F38: 00:47 | G38: 00:52 | H38: 5 | I38: Gamma / Claude Design
A39: 4 | B39: Herramientas IA: NotebookLM, Claude Design, Gamma y Codex | C39: 4.3 | D39: Ejercicio 4.3: práctica de alumnos — Presentación rápida desde minuta: estructura para Gamma y mejora visual con Claude Design | E39: Ejercicio - práctica alumnos | F39: 00:52 | G39: 01:02 | H39: 10 | I39: Gamma / Claude Design
A40: 4 | B40: Herramientas IA: NotebookLM, Claude Design, Gamma y Codex | C40: 4.4 | D40: Ejercicio 4.4: explicación del resultado esperado — Codex/Claude Code: convertir un requerimiento en plantilla operativa o dashboard simple | E40: Ejercicio - explicación | F40: 01:02 | G40: 01:05 | H40: 3 | I40: Codex / Claude Code
...

Sheet Matriz Ejercicios
A1: Clase | B1: Código | C1: Título del ejercicio | D1: Objetivo | E1: Insumo requerido | F1: Herramientas | G1: Minutos alumnos | H1: Entregable | I1: Requerimiento asociado | J1: Dificultad | K1: Criterio de evaluación
A2: 2 | B2: 2.1 | C2: Minuta automática y matriz de compromisos | D2: Extraer acuerdos, tareas, responsables, plazos, riesgos y prioridades desde una transcripción | E2: Transcripción de reunión o audio convertido a texto | F2: ChatGPT / Claude / Gemini | G2: 10 | H2: Tabla de compromisos + resumen ejecutivo | I2: Gestión de reuniones | J2: Básico | K2: Criterio: claridad de responsables, plazos y prioridades
A3: 2 | B3: 2.2 | C3: Correo de seguimiento ejecutivo | D3: Redactar correos según objetivo, destinatario, tono y próximos pasos | E3: Minuta o lista de acuerdos | F3: ChatGPT / Copilot | G3: 10 | H3: Correo listo para enviar | I3: Productividad diaria | J3: Básico | K3: Criterio: tono profesional, precisión y acción concreta
A4: 2 | B4: 2.3 | C4: Refinamiento de prompt hacia salida controlada | D4: Pasar de una instrucción abierta a un prompt con reglas, formato y validación | E4: Texto desordenado o caso operativo | F4: ChatGPT / Claude | G4: 10 | H4: Prompt final + tabla estructurada | I4: Prompting | J4: Básico | K4: Criterio: salida repetible y sin ambigüedad
A5: 3 | B5: 3.1 | C5: Análisis de prospección comercial | D5: Calcular rendimiento por segmento, día y asunto, y recomendar acciones | E5: Excel/CSV de envíos de correos | F5: ChatGPT con análisis de datos | G5: 10 | H5: Tabla + gráfico + recomendación | I5: Análisis de datos | J5: Intermedio | K5: Criterio: métricas correctas y conclusión accionable
A6: 3 | B6: 3.2 | C6: Indicadores por departamento | D6: Analizar datos o procedimientos de Calidad, Oficina Técnica, Planificación y RR.HH. | E6: Planilla de indicadores o procedimiento interno | F6: ChatGPT / Claude + Excel | G6: 10 | H6: Resumen por área + riesgos + puntos débiles | I6: Solicitud Cinecta | J6: Intermedio | K6: Criterio: hallazgos útiles para cada departamento
A7: 3 | B7: 3.3 | C7: Auditoría de planilla | D7: Detectar duplicados, outliers, errores y datos faltantes antes de tomar decisiones | E7: Excel con registros operativos | F7: ChatGPT / Excel | G7: 10 | H7: Lista de errores + acciones correctivas | I7: Calidad de datos | J7: Intermedio | K7: Criterio: detectar errores sin inventar datos
A8: 4 | B8: 4.1 | C8: NotebookLM para procedimientos internos | D8: Convertir documentos largos en resúmenes, reglas y respuestas fundamentadas | E8: PDF de reglamento/procedimiento | F8: NotebookLM | G8: 10 | H8: Resumen ejecutivo + preguntas y respuestas | I8: Herramientas documentales | J8: Básico | K8: Criterio: responder solo con base en documentos
A9: 4 | B9: 4.2 | C9: Contraste contrato vs normativa interna | D9: Comparar condiciones de un contrato/propuesta contra normas internas financieras | E9: Bases de contrato + política interna | F9: NotebookLM / ChatGPT | G9: 10 | H9: Tabla de cumplimiento, riesgo y recomendación | I9: Solicitud Finanzas | J9: Intermedio | K9: Criterio: identificar cumple/no cumple/requiere aprobación
A10: 4 | B10: 4.3 | C10: Presentación rápida desde minuta | D10: Transformar una reunión en estructura de presentación ejecutiva | E10: Minuta o transcripción | F10: Gamma / Claude Design | G10: 10 | H10: Guion y deck editable | I10: Presentaciones rápidas | J10: Intermedio | K10: Criterio: claridad ejecutiva y consistencia visual
A11: 4 | B11: 4.4 | C11: Codex/Claude Code para plantilla operativa | D11: Convertir un requerimiento en estructura de archivo, dashboard o plantilla | E11: Requerimiento escrito | F11: Codex / Claude Code | G11: 10 | H11: Prototipo o plantilla base | I11: Herramientas técnicas | J11: Avanzado básico | K11: Criterio: instrucciones claras y resultado utilizable
A12: 5 | B12: 5.1 | C12: Asistente de reunión completo | D12: Transformar audio/transcripción en minuta, compromisos y correos de seguimiento | E12: Audio/transcripción de reunión | F12: Read AI / Otter / ChatGPT / Gmail | G12: 10 | H12: Minuta + correo + matriz de tareas | I12: Solicitud reuniones | J12: Intermedio | K12: Criterio: flujo completo y revisión humana
A13: 5 | B13: 5.2 | C13: Agente documental simple | D13: Crear instrucciones persistentes para revisar archivos y generar entregables | E13: Formato base + tabla de reglas + transcripción | F13: ChatGPT Projects / Custom GPT / Claude | G13: 10 | H13: Agente o instrucciones reutilizables | I13: Agentes | J13: Intermedio | K13: Criterio: no inventar y respetar fuentes
... A18: 7 | B18: 7.1 | C18: Mapa de oportunidades IA por área | D18: Priorizar quick wins por impacto, esfuerzo, riesgo y datos disponibles | E18: Procesos reales de Cinecta | F18: Matriz impacto/esfuerzo | G18: 10 | H18: Backlog priorizado de oportunidades | I18: Proyecto final | J18: Intermedio | K18: Criterio: caso aplicable y acotado

Sheet Proyecto Final
A1: Proyecto final aplicado - Cinecta
A2: Objetivo | B2: Diseñar un caso de uso real de IA aplicable a un proceso de Cinecta, con flujo, entregable, controles y próximos pasos.
A3: Formato sugerido | B3: Equipos o individual. Presentación de 5 diapositivas + demo, prompt, agente o flujo conceptual.
A5: Etapa | B5: Clase | C5: Actividad | D5: Entregable esperado | E5: Tiempo sugerido | F5: Observaciones
A6: 1 | B6: Clase 2 | C6: Definir problema y prompt base | D6: Problema + prompt ROCEF inicial | E6: Durante clase / tarea | F6: Elegir un proceso real y acotado
A7: 2 | B7: Clase 3 | C7: Identificar datos o documentos necesarios | D7: Lista de datos, fuentes y riesgos de calidad | E7: Durante clase / tarea | F7: Evitar depender de datos inexistentes
A8: 3 | B8: Clase 4 | C8: Seleccionar herramienta principal | D8: Justificación de herramienta | E8: Durante clase / tarea | F8: NotebookLM, Gamma, Claude Design, Codex, etc.
A9: 4 | B9: Clase 5 | C9: Convertirlo en asistente, plantilla o flujo básico | D9: Prototipo funcional o instrucciones del agente | E9: Durante clase | F9: Debe incluir revisión humana
A10: 5 | B10: Clase 6 | C10: Escalar a automatización avanzada si aplica | D10: Diagrama no-code/MCP/agente | E10: Durante clase | F10: Solo si aporta valor y es viable
A11: 6 | B11: Clase 7 | C11: Preparar presentación y recibir feedback | D11: Versión final del proyecto | E11: Durante clase | F11: Ajustar alcance y entregables
A12: 7 | B12: Clase 8 | C12: Presentar solución | D12: Pitch + demo + siguientes pasos | E12: 7 minutos por equipo | F12: Ajustable según número de equipos
A14: Rúbrica | B14: Peso | C14: Descripción | D14: Nivel alto | E14: Nivel medio | F14: Nivel bajo
A15: Problema y valor de negocio | B15: 25 | C15: Claridad del dolor y beneficio esperado | D15: Caso crítico, concreto y medible | E15: Caso relevante pero poco medible | F15: Caso general o poco conectado
A16: Calidad del prompt/agente/flujo | B16: 25 | C16: Diseño de instrucciones, fuentes y proceso | D16: Estructura clara, controlada y reutilizable | E16: Funciona pero requiere ajustes | F16: Instrucciones vagas o no reproducibles
A17: Uso adecuado de herramientas | B17: 20 | C17: Selección correcta de herramienta para el problema | D17: Herramienta bien justificada | E17: Herramienta útil pero no óptima | F17: Herramienta elegida sin criterio
A18: Control de riesgos y privacidad | B18: 15 | C18: Validación humana, permisos, datos sensibles y trazabilidad | D18: Riesgos identificados y mitigados | E18: Riesgos mencionados superficialmente | F18: Sin control de riesgos
A19: Presentación y aplicabilidad | B19: 15 | C19: Claridad del pitch y potencial de implementación | D19: Próximos pasos claros y aplicables | E19: Aplicabilidad parcial | F19: Difícil de implementar
A20: Total | B20: =SUM(B15:B19) -> 100
