Workbook

Sheet Planificación
A1: Clase | B1: Nombre clase | C1: Ejercicio | D1: Actividad / título | E1: Tipo | F1: Inicio | G1: Término | H1: Duración min | I1: Herramientas / conceptos
A2: 1 | B2: Contexto y marco de trabajo | D2: Inicio y presentación: contexto del curso, objetivos, expectativas y reglas de trabajo | E2: Inicio | F2: 00:00 | G2: 00:20 | H2: 20
A3: 1 | B3: Contexto y marco de trabajo | D3: Objetivo general: aplicar IA al desarrollo de software para acelerar construcción, automatización, testing y diseño de agentes en Anagra | E3: Teoría aplicada | F3: 00:20 | G3: 00:30 | H3: 10
A4: 1 | B4: Contexto y marco de trabajo | D4: Panorama actual de IA aplicada al desarrollo: herramientas, modelos y tendencias recientes | E4: Teoría aplicada | F4: 00:30 | G4: 00:35 | H4: 5 | I4: Claude / OpenAI / Copilot
A5: 1 | B5: Contexto y marco de trabajo | D5: Metodología para programar con IA: de prompting a Context Engineering y Spec-Driven Development | E5: Teoría aplicada | F5: 00:35 | G5: 00:40 | H5: 5 | I5: SDD / Context Engineering
A6: 1 | B6: Contexto y marco de trabajo | D6: Demostración 1: asistentes de código en IDE | E6: Demostración | F6: 00:40 | G6: 00:55 | H6: 15 | I6: Claude Code / Codex / Copilot / Cursor
A7: 1 | B7: Contexto y marco de trabajo | D7: Demostración 2: n8n generando flujos con IA y primer vistazo a MCP nativo | E7: Demostración | F7: 00:55 | G7: 01:10 | H7: 15 | I7: n8n / MCP
A8: 1 | B8: Contexto y marco de trabajo | D8: Demostración 3: uso de agentes para control de una empresa | E8: Demostración | F8: 01:10 | G8: 01:25 | H8: 15 | I8: Agentes / n8n / IA
A9: 1 | B9: Contexto y marco de trabajo | D9: Cierre y preguntas | E9: Preguntas alumnos | F9: 01:25 | G9: 01:30 | H9: 5
A10: 2 | B10: Herramientas modernas y desarrollo asistido por IA | D10: Apertura: tendencia actual de asistentes de código integrados al IDE | E10: Inicio | F10: 00:00 | G10: 00:05 | H10: 5 | I10: Claude Code / Codex / Copilot / Cursor
A11: 2 | B11: Herramientas modernas y desarrollo asistido por IA | C11: 2.1 | D11: Ejercicio 2.1: explicación — desarrollo asistido con Claude Code en el IDE | E11: Ejercicio - explicación | F11: 00:05 | G11: 00:10 | H11: 5 | I11: Claude Code
A12: 2 | B12: Herramientas modernas y desarrollo asistido por IA | C12: 2.1 | D12: Ejercicio 2.1: demostración profesor — crear o modificar una funcionalidad con IA | E12: Ejercicio - demo profesor | F12: 00:10 | G12: 00:20 | H12: 10 | I12: Claude Code
A13: 2 | B13: Herramientas modernas y desarrollo asistido por IA | C13: 2.1 | D13: Ejercicio 2.1: práctica alumnos — desarrollo asistido sobre caso guiado | E13: Ejercicio - práctica alumnos | F13: 00:20 | G13: 00:30 | H13: 10 | I13: Claude Code
A14: 2 | B14: Herramientas modernas y desarrollo asistido por IA | C14: 2.2 | D14: Ejercicio 2.2: explicación — refactor, debugging y documentación con Codex | E14: Ejercicio - explicación | F14: 00:30 | G14: 00:35 | H14: 5 | I14: Codex
A15: 2 | B15: Herramientas modernas y desarrollo asistido por IA | C15: 2.2 | D15: Ejercicio 2.2: demostración profesor — análisis y mejora de código existente | E15: Ejercicio - demo profesor | F15: 00:35 | G15: 00:45 | H15: 10 | I15: Codex
A16: 2 | B16: Herramientas modernas y desarrollo asistido por IA | C16: 2.2 | D16: Ejercicio 2.2: práctica alumnos — refactor o debugging asistido | E16: Ejercicio - práctica alumnos | F16: 00:45 | G16: 00:55 | H16: 10 | I16: Codex
A17: 2 | B17: Herramientas modernas y desarrollo asistido por IA | C17: 2.3 | D17: Ejercicio 2.3: explicación — uso de Copilot/Cursor en flujo real de trabajo | E17: Ejercicio - explicación | F17: 00:55 | G17: 01:00 | H17: 5 | I17: Copilot / Cursor
A18: 2 | B18: Herramientas modernas y desarrollo asistido por IA | C18: 2.3 | D18: Ejercicio 2.3: demostración profesor — asistencia en IDE, sugerencias y pruebas | E18: Ejercicio - demo profesor | F18: 01:00 | G18: 01:10 | H18: 10 | I18: Copilot / Cursor
A19: 2 | B19: Herramientas modernas y desarrollo asistido por IA | C19: 2.3 | D19: Ejercicio 2.3: práctica alumnos — uso asistido en entorno de desarrollo | E19: Ejercicio - práctica alumnos | F19: 01:10 | G19: 01:20 | H19: 10 | I19: Copilot / Cursor
A20: 2 | B20: Herramientas modernas y desarrollo asistido por IA | D20: Resolver dudas | E20: Preguntas alumnos | F20: 01:20 | G20: 01:30 | H20: 10
A21: 3 | B21: Automatización con n8n y MCP | D21: Apertura: de asistentes de código a automatización de procesos | E21: Inicio | F21: 00:00 | G21: 00:08 | H21: 8 | I21: n8n / Make / MCP
A22: 3 | B22: Automatización con n8n y MCP | D22: Demo inicial: n8n como cliente/servidor MCP y generación de workflows con IA | E22: Demostración | F22: 00:08 | G22: 00:20 | H22: 12 | I22: n8n MCP Server / MCP Client Tool
A23: 3 | B23: Automatización con n8n y MCP | C23: 3.1 | D23: Ejercicio 3.1: explicación — creación de workflow con IA en n8n | E23: Ejercicio - explicación | F23: 00:20 | G23: 00:25 | H23: 5 | I23: n8n
A24: 3 | B24: Automatización con n8n y MCP | C24: 3.1 | D24: Ejercicio 3.1: demostración profesor — generar un flujo automatizado con IA | E24: Ejercicio - demo profesor | F24: 00:25 | G24: 00:33 | H24: 8 | I24: n8n
A25: 3 | B25: Automatización con n8n y MCP | C25: 3.1 | D25: Ejercicio 3.1: práctica alumnos — creación de flujo guiado | E25: Ejercicio - práctica alumnos | F25: 00:33 | G25: 00:43 | H25: 10 | I25: n8n
A26: 3 | B26: Automatización con n8n y MCP | C26: 3.2 | D26: Ejercicio 3.2: explicación — webhooks, APIs y conexión entre herramientas | E26: Ejercicio - explicación | F26: 00:43 | G26: 00:48 | H26: 5 | I26: n8n / APIs
A27: 3 | B27: Automatización con n8n y MCP | C27: 3.2 | D27: Ejercicio 3.2: demostración profesor — integración simple entre sistemas | E27: Ejercicio - demo profesor | F27: 00:48 | G27: 00:58 | H27: 10 | I27: n8n / APIs
A28: 3 | B28: Automatización con n8n y MCP | C28: 3.2 | D28: Ejercicio 3.2: práctica alumnos — conectar servicios y procesar información | E28: Ejercicio - práctica alumnos | F28: 00:58 | G28: 01:08 | H28: 10 | I28: n8n / APIs
A29: 3 | B29: Automatización con n8n y MCP | C29: 3.3 | D29: Ejercicio 3.3: explicación — IA dentro de un flujo automatizado y herramientas MCP | E29: Ejercicio - explicación | F29: 01:08 | G29: 01:12 | H29: 4 | I29: n8n / IA / MCP
A30: 3 | B30: Automatización con n8n y MCP | C30: 3.3 | D30: Ejercicio 3.3: demostración profesor — clasificar, generar respuesta o notificar con IA | E30: Ejercicio - demo profesor | F30: 01:12 | G30: 01:20 | H30: 8 | I30: n8n / IA
A31: 3 | B31: Automatización con n8n y MCP | C31: 3.3 | D31: Ejercicio 3.3: práctica alumnos — automatización aplicada a caso guiado | E31: Ejercicio - práctica alumnos | F31: 01:20 | G31: 01:25 | H31: 5 | I31: n8n / IA
A32: 3 | B32: Automatización con n8n y MCP | D32: Cierre: dudas y aprendizajes de automatización | E32: Cierre | F32: 01:25 | G32: 01:30 | H32: 5
A33: 4 | B33: Context Engineering y Spec-Driven Development | D33: Apertura: de prompts sueltos a especificaciones claras para programar con IA | E33: Inicio | F33: 00:00 | G33: 00:08 | H33: 8 | I33: SDD / Context Engineering
A34: 4 | B34: Context Engineering y Spec-Driven Development | C34: 4.1 | D34: Ejercicio 4.1: explicación — diseño de contexto efectivo para asistentes de código | E34: Ejercicio - explicación | F34: 00:08 | G34: 00:13 | H34: 5 | I34: Claude Code / Codex
A35: 4 | B35: Context Engineering y Spec-Driven Development | C35: 4.1 | D35: Ejercicio 4.1: demostración profesor — mejorar resultados usando contexto estructurado | E35: Ejercicio - demo profesor | F35: 00:13 | G35: 00:20 | H35: 7 | I35: Claude / ChatGPT
A36: 4 | B36: Context Engineering y Spec-Driven Development | C36: 4.1 | D36: Ejercicio 4.1: práctica alumnos — construir contexto para un caso técnico | E36: Ejercicio - práctica alumnos | F36: 00:20 | G36: 00:32 | H36: 12 | I36: Claude / ChatGPT
A37: 4 | B37: Context Engineering y Spec-Driven Development | C37: 4.2 | D37: Ejercicio 4.2: explicación — Spec-Driven Development y flujo tipo spec-kit | E37: Ejercicio - explicación | F37: 00:32 | G37: 00:42 | H37: 10 | I37: Spec Kit / SDD
A38: 4 | B38: Context Engineering y Spec-Driven Development | C38: 4.2 | D38: Ejercicio 4.2: demostración profesor — idea → constitución → spec → plan técnico → tareas | E38: Ejercicio - demo profesor | F38: 00:42 | G38: 00:52 | H38: 10 | I38: Spec Kit / Claude Code
A39: 4 | B39: Context Engineering y Spec-Driven Development | C39: 4.2 | D39: Ejercicio 4.2: práctica alumnos — convertir una idea en especificación accionable | E39: Ejercicio - práctica alumnos | F39: 00:52 | G39: 01:07 | H39: 15 | I39: SDD
A40: 4 | B40: Context Engineering y Spec-Driven Development | C40: 4.3 | D40: Ejercicio 4.3: explicación — memoria, tokens, latencia y costo | E40: Ejercicio - explicación | F40: 01:07 | G40: 01:12 | H40: 5 | I40: Claude / OpenAI
...

Sheet Resumen
A1: Clase | B1: Nombre clase | C1: Minutos planificados | D1: Horas | E1: Estado
A2: 1 | B2: Contexto y marco de trabajo | C2: =SUM(Planificación!H2:H9) -> 90 | D2: =C2/60 -> 1.5 | E2: =IF(C2=90,"OK","Revisar") -> OK
A3: 2 | B3: Herramientas modernas y desarrollo asistido por IA | C3: =SUM(Planificación!H10:H20) -> 90 | D3: =C3/60 -> 1.5 | E3: =IF(C3=90,"OK","Revisar") -> OK
A4: 3 | B4: Automatización con n8n y MCP | C4: =SUM(Planificación!H21:H32) -> 90 | D4: =C4/60 -> 1.5 | E4: =IF(C4=90,"OK","Revisar") -> OK
A5: 4 | B5: Context Engineering y Spec-Driven Development | C5: =SUM(Planificación!H33:H42) -> 90 | D5: =C5/60 -> 1.5 | E5: =IF(C5=90,"OK","Revisar") -> OK
A6: 5 | B6: Construcción de agente básico con MCP | C6: =SUM(Planificación!H43:H51) -> 90 | D6: =C6/60 -> 1.5 | E6: =IF(C6=90,"OK","Revisar") -> OK
A7: 6 | B7: MCP y orquestación multiagente | C7: =SUM(Planificación!H52:H61) -> 90 | D7: =C7/60 -> 1.5 | E7: =IF(C7=90,"OK","Revisar") -> OK
A8: 7 | B8: Resumen, preguntas y proyecto aplicado | C8: =SUM(Planificación!H62:H67) -> 90 | D8: =C8/60 -> 1.5 | E8: =IF(C8=90,"OK","Revisar") -> OK
A9: 8 | B9: Presentaciones y proyectos de alumnos | C9: =SUM(Planificación!H68:H70) -> 90 | D9: =C9/60 -> 1.5 | E9: =IF(C9=90,"OK","Revisar") -> OK
A11: Total curso | C11: =SUM(C2:C9) -> 720 | D11: =C11/60 -> 12 | E11: =IF(C11=720,"OK","Revisar") -> OK

Sheet Referencias
A1: Tema | B1: Fuente / URL | C1: Uso en planificación
A2: Temario base Anagra | B2: PDF cargado en la conversación: Anagra_Temario_IA_Aplicada_Desarrollo_Software | C2: Base de módulos, duración total y enfoque del curso.
A3: n8n MCP Server | B3: https://blog.n8n.io/n8n-mcp-server/ | C3: Clase 1 y 3: demo de n8n con MCP nativo y generación de workflows con IA.
A4: n8n MCP Client Tool | B4: https://docs.n8n.io/integrations/builtin/cluster-nodes/sub-nodes/n8n-nodes-langchain.toolmcp/ | C4: Clase 3: n8n como cliente MCP conectado a herramientas externas.
A5: n8n MCP Server Trigger | B5: https://docs.n8n.io/integrations/builtin/core-nodes/n8n-nodes-langchain.mcptrigger/ | C5: Clase 3: n8n como servidor MCP que expone herramientas a clientes MCP.
A6: GitHub Spec Kit | B6: https://github.com/github/spec-kit | C6: Clase 4: Spec-Driven Development como metodología de trabajo.
A7: GitHub blog Spec-Driven Development | B7: https://github.blog/ai-and-ml/generative-ai/spec-driven-development-with-ai-get-started-with-a-new-open-source-toolkit/ | C7: Clase 4: flujo de spec → plan técnico → tareas con agentes de código.
A8: Model Context Protocol | B8: https://modelcontextprotocol.io/specification/2025-11-25 | C8: Clases 5 y 6: diseño de agentes, MCP, seguridad y herramientas.
