Workbook

Sheet Dashboard
A1: SQM – Dashboard financiero base para decisión de inversión
A4: Inputs de mercado (editables) | J4: Año | K4: Ingresos | L4: CFO
A5: Precio ADR SQM (USD) | B5: 87.81 | J5: 2024 | K5: =C13 -> 4528761 | L5: =C18 -> 1274678
A6: Acciones en circulación (millones) | B6: 285.64 | J6: 2025 | K6: =B13 -> 4576224 | L6: =B18 -> 1314367
A7: Fecha precio | B7: 2026-04-15 13:38 EDT
A8: P/E trailing de referencia | B8: 43.19
J10: Segmento 2025 | K10: Ingresos
A11: Métricas financieras resumidas | J11: Nutrición vegetal de especialidad | K11: 982397
A12: Métrica | B12: 2025 | C12: 2024 | D12: Var.% | E12: Lectura | F12: Base | G12: Fuente | J12: Yodo y derivados | K12: 1042780
A13: Ingresos | B13: =EEFF!B62 -> 4576224 | C13: =EEFF!C62 -> 4528761 | D13: =IFERROR(B13/C13-1,"") -> 0.01048035 | E13: Leve alza | F13: Estado de resultados | G13: p.19 | J13: Litio y derivados | K13: 2288245
A14: Ganancia bruta | B14: =EEFF!B64 -> 1352600 | C14: =EEFF!C64 -> 1327107 | D14: =IFERROR(B14/C14-1,"") -> 0.019209453 | E14: Margen estable | F14: Estado de resultados | G14: p.19 | J14: Químicos industriales | K14: 75402
A15: Ganancia operacional | B15: =EEFF!B70 -> 1063060 | C15: =EEFF!C70 -> 1065898 | D15: =IFERROR(B15/C15-1,"") -> -0.0026625437 | E15: EBIT estable | F15: Estado de resultados | G15: p.19 | J15: Potasio | K15: 155507
A16: Ganancia neta | B16: =EEFF!B77 -> 640643 | C16: =EEFF!C77 -> -397635 | D16: =IFERROR(B16/C16-1,"") -> -2.6111333 | E16: Vuelta a utilidad | F16: Estado de resultados | G16: p.19 | J16: Otros productos y servicios | K16: 31893
A17: EBITDA aprox. | B17: =B15+422564 -> 1485624 | C17: =C15+342424 -> 1408322 | D17: =IFERROR(B17/C17-1,"") -> 0.054889436 | E17: Mejora operativa | F17: EBIT + D&A segmentado | G17: pp.155-156
A18: Flujo operativo | B18: =EEFF!B94 -> 1314367 | C18: =EEFF!C94 -> 1274678 | D18: =IFERROR(B18/C18-1,"") -> 0.031136491 | E18: Caja operativa al alza | F18: CFO | G18: pp.21-22
A19: Capex | B19: =-EEFF!B100 -> 876676 | C19: =-EEFF!C100 -> 971792 | D19: =IFERROR(B19/C19-1,"") -> -0.097876912 | E19: Capex algo menor | F19: Capex bruto | G19: p.21
A20: Flujo libre aprox. | B20: =B18-B19 -> 437691 | C20: =C18-C19 -> 302886 | D20: =IFERROR(B20/C20-1,"") -> 0.44506844 | E20: FCF mejora fuerte | F20: CFO - Capex | G20: pp.21-22
A21: Caja y equivalentes | B21: =EEFF!B6 -> 1750321 | C21: =EEFF!C6 -> 1377851 | D21: =IFERROR(B21/C21-1,"") -> 0.27032676 | E21: Caja sube | F21: Balance | G21: p.17
A22: Deuda financiera total | B22: =4691312 -> 4691312 | C22: =4764050 -> 4764050 | D22: =IFERROR(B22/C22-1,"") -> -0.015268102 | E22: Deuda baja levemente | F22: Nota 13.4 | G22: p.86
A23: Patrimonio controladora | B23: =EEFF!B56 -> 5691262 | C23: =EEFF!C56 -> 5160819 | D23: =IFERROR(B23/C23-1,"") -> 0.10278272 | E23: Equity crece | F23: Balance | G23: p.18
A24: Activos totales | B24: =EEFF!B29 -> 14504960 | C24: =EEFF!C29 -> 11495569 | D24: =IFERROR(B24/C24-1,"") -> 0.26178704 | E24: Balance crece | F24: Balance | G24: p.17
A27: Ratios y valoración
A28: Ratio | B28: 2025 | C28: 2024 | D28: Lectura | E28: Interpretación | F28: Base | G28: Fuente
A29: Margen bruto | B29: =B14/B13 -> 0.2955712 | C29: =C14/C13 -> 0.29303975 | D29: Fuerte si >28% | E29: Mejor que 2024 | F29: Ganancia bruta / Ingresos | G29: p.19
A30: Margen operacional | B30: =B15/B13 -> 0.23230069 | C30: =C15/C13 -> 0.23536195 | D30: Fuerte si >20% | E30: Sólido | F30: EBIT / Ingresos | G30: p.19
A31: Margen neto | B31: =B16/B13 -> 0.1399938 | C31: =C16/C13 -> -0.08780216 | D31: Salud final | E31: Recuperado | F31: Utilidad neta / Ingresos | G31: p.19
A32: Margen CFO | B32: =B18/B13 -> 0.28721649 | C32: =C18/C13 -> 0.28146285 | D32: Caja operativa | E32: Sólido | F32: CFO / Ingresos | G32: pp.21-22
A33: Current ratio | B33: =EEFF!B15/EEFF!B41 -> 3.2679649 | C33: =EEFF!C15/EEFF!C41 -> 2.5141517 | D33: Liquidez | E33: Holgado | F33: Activos corrientes / Pasivos corrientes | G33: pp.17-18
A34: Deuda / patrimonio controladora | B34: =B22/B23 -> 0.82430083 | C34: =C22/C23 -> 0.92311899 | D34: Apalancamiento | E34: Menor es mejor | F34: Deuda financiera / Equity controladora | G34: pp.18, 86
A35: Deuda / activos | B35: =B22/B24 -> 0.32342812 | C35: =C22/C24 -> 0.4144249 | D35: Estructura | E35: Menor es mejor | F35: Deuda financiera / Activos | G35: pp.17, 86
A36: ROA | B36: =B16/B24 -> 0.044167168 | C36: =C16/C24 -> -0.034590284 | D36: Rentabilidad | E36: Positivo | F36: Utilidad neta / Activos | G36: pp.17,19
A37: ROE controladora | B37: =EEFF!B78/B23 -> 0.10334052 | C37: =EEFF!C78/C23 -> -0.078351711 | D37: Rentabilidad accionista | E37: Positivo | F37: Utilidad controladora / Equity controladora | G37: pp.18-19
A38: Capex / CFO | B38: =B19/B18 -> 0.66699483 | C38: =C19/C18 -> 0.76238234 | D38: Intensidad inversión | E38: Menor es mejor | F38: Capex / CFO | G38: pp.21-22
A39: Tasa efectiva de impuesto | B39: =-EEFF!B76/EEFF!B75 -> 0.33316783 | C39: =-EEFF!C76/EEFF!C75 -> 1.408076 | D39: Carga tributaria | E39: 33% razonable vs 2024 | F39: Impuesto / PBT | G39: pp.19,176
A40: BVPS controladora (USD) | B40: =B23/($B$6*1000) -> 19.924597 | C40: =C23/($B$6*1000) -> 18.067564 | D40: Valor libro/acción | E40: Base patrimonial | F40: Equity controladora / acciones | G40: pp.18 + web
A41: P/B implícito | B41: =$B$5/B40 -> 4.4071154 | C41: =$B$5/C40 -> 4.8600907 | D41: Múltiplo patrimonial | E41: No luce barato | F41: Precio / BVPS | G41: pp.18 + web
A42: Market cap implícito (US$ MM) | B42: =$B$5*$B$6 -> 25082.048 | C42: =$B$5*$B$6 -> 25082.048 | D42: Cap. bursátil | E42: Tamaño bursátil | F42: Precio x acciones | G42: web
A43: EV aprox. (US$ MM) | B43: =B42+B22/1000-B21/1000 -> 28023.039 | C43: =C42+C22/1000-C21/1000 -> 28468.247 | D43: Valor empresa | E43: Valor empresa alto | F43: Market cap + deuda - caja | G43: web + EEFF
A44: EV / EBITDA aprox. | B44: =B43/(B17/1000) -> 18.862807 | C44: =C43/(C17/1000) -> 20.214303 | D44: Múltiplo operativo | E44: No luce bajo | F44: EV / EBITDA aprox. | G44: web + EEFF

Sheet EEFF
A1: SQM – Estados financieros clave 2025 vs 2024
A3: Concepto | B3: 2025 | C3: 2024 | D3: Var. abs.
A4: Estado de situación financiera – Activos
A5: Activos corrientes
A6: Efectivo y equivalentes al efectivo | B6: 1750321 | C6: 1377851 | D6: 372470
A7: Otros activos financieros corrientes | B7: 976641 | C7: 1079595 | D7: -102954
A8: Otros activos no financieros corrientes | B8: 122288 | C8: 200705 | D8: -78417
A9: Deudores comerciales y otras cuentas por cobrar corrientes | B9: 649055 | C9: 606137 | D9: 42918
A10: Cuentas por cobrar a entidades relacionadas corrientes | B10: 36799 | C10: 28706 | D10: 8093
A11: Inventarios corrientes | B11: 1803478 | C11: 1702185 | D11: 101293
A12: Activos por impuestos corrientes | B12: 441794 | C12: 583143 | D12: -141349
A13: Total activos corrientes distintos de activos mantenidos para la venta | B13: 5780376 | C13: 5578322 | D13: 202054
A14: Activos mantenidos para la venta | B14: 118 | C14: 118 | D14: 0
A15: Total activos corrientes | B15: 5780494 | C15: 5578440 | D15: 202054
A17: Activos no corrientes
A18: Otros activos financieros no corrientes | B18: 76244 | C18: 60706 | D18: 15538
A19: Otros activos no financieros no corrientes | B19: 314348 | C19: 364166 | D19: -49818
A20: Cuentas por cobrar no corrientes | B20: 3295 | C20: 2727 | D20: 568
A21: Inversiones método de participación | B21: 631199 | C21: 585794 | D21: 45405
A22: Activos intangibles distintos de la plusvalía | B22: 2553052 | C22: 167968 | D22: 2385084
A23: Plusvalía | B23: 958 | C23: 948 | D23: 10
A24: Propiedades, plantas y equipos | B24: 4839490 | C24: 4433645 | D24: 405845
A25: Activos por derechos de uso | B25: 70336 | C25: 84070 | D25: -13734
A26: Activos por impuestos no corrientes | B26: 59541 | C26: 59541 | D26: 0
A27: Activos por impuestos diferidos | B27: 176003 | C27: 157564 | D27: 18439
A28: Total activos no corrientes | B28: 8724466 | C28: 5917129 | D28: 2807337
A29: Total activos | B29: 14504960 | C29: 11495569 | D29: 3009391
A31: Estado de situación financiera – Pasivos y patrimonio
A32: Pasivos corrientes
A33: Otros pasivos financieros corrientes | B33: 470755 | C33: 1163468 | D33: -692713
A34: Pasivos por arrendamiento corrientes | B34: 22196 | C34: 23011 | D34: -815
A35: Cuentas por pagar comerciales y otras cuentas por pagar corrientes | B35: 384220 | C35: 471449 | D35: -87229
A36: Cuentas por pagar a entidades relacionadas corrientes | B36: 53406 | C36: 10265 | D36: 43141
A37: Otras provisiones corrientes | B37: 320005 | C37: 311197 | D37: 8808
A38: Pasivos por impuestos corrientes | B38: 113094 | C38: 79841 | D38: 33253
A39: Provisiones por beneficios a los trabajadores corrientes | B39: 68093 | C39: 31546 | D39: 36547
A40: Otros pasivos no financieros corrientes | B40: 337067 | C40: 128039 | D40: 209028
A41: Total pasivos corrientes | B41: 1768836 | C41: 2218816 | D41: -449980
A43: Pasivos no corrientes
A44: Otros pasivos financieros no corrientes | B44: 4220557 | C44: 3600582 | D44: 619975
...

Sheet NotasClave
A1: SQM – Notas clave para análisis financiero
A2: Tablas de inventarios, deuda, intangibles, PP&E, impuestos y riesgos materiales.
A4: Inventarios y provisiones
A5: Concepto | B5: 2025 | C5: 2024 | D5: Detalle
A6: Materia prima y suministros para la producción | B6: 299261 | C6: 150126
A7: Productos en proceso | B7: 603903 | C7: 698134
A8: Productos terminados | B8: 900314 | C8: 853925
A9: Total inventarios | B9: 1803478 | C9: 1702185
A10: Inventarios a granel en proceso | B10: 162934 | C10: 249105
A11: Inventarios a granel terminados | B11: 243756 | C11: 138625
A12: Provisión materias primas | B12: 16571 | C12: 5082
A13: Provisión productos en proceso | B13: 72477 | C13: 75100
A14: Provisión productos terminados | B14: 22389 | C14: 34450
A15: Total provisiones de inventario | B15: 111437 | C15: 114632
A18: Deuda financiera – resumen
A19: Concepto | B19: Corriente 2025 | C19: No corriente 2025 | D19: Total 2025 | E19: Total 2024
A20: Préstamos bancarios | B20: 379667 | C20: 293291 | D20: 672958 | E20: 977646
A21: Obligaciones con el público | B21: 56802 | C21: 3925475 | D21: 3982277 | E21: 3757230
A22: Derivados con fines de cobertura | B22: 30237 | C22: 1791 | D22: 32028 | E22: 28756
A23: Derivados con fines de no cobertura | B23: 4049 | C23: 0 | D23: 4049 | E23: 418
A24: Total otros pasivos financieros | B24: 470755 | C24: 4220557 | D24: 4691312 | E24: 4764050
A26: Bonos / obligaciones no garantizadas
A27: Serie | B27: Vencimiento | C27: Moneda | D27: Valor libro 2025
A28: MMUS$450 | B28: 2029-05-07 | C28: US$ | D28: 448360
A29: MMUS$400 | B29: 2050-01-22 | C29: US$ | D29: 394585
A30: MMUS$700 | B30: 2051-09-10 | C30: US$ | D30: 686316
A31: MMUS$750 | B31: 2033-11-07 | C31: US$ | D31: 739017
A32: MMUS$850 | B32: 2034-09-10 | C32: US$ | D32: 835145
A33: H | B33: 2030-01-05 | C33: UF | D33: 55222
A34: O | B34: 2033-02-01 | C34: UF | D34: 65197
A35: P | B35: 2028-01-15 | C35: UF | D35: 131370
A36: Q | B36: 2038-06-01 | C36: UF | D36: 131138
A37: S | B37: 2058-02-15 | C37: UF | D37: 439125
A40: Activos intangibles
A41: Concepto | B41: 2025 | C41: 2024 | D41: Vida útil
A42: Programas informáticos | B42: 11913 | C42: 8430 | D42: Finita
A43: Pertenencia minera | B43: 133073 | C43: 133119 | D43: Finita
A44: Derechos de agua y servidumbres | B44: 4909 | C44: 4909 | D44: Indefinida
A45: Derechos de agua | B45: 0 | C45: 3791 | D45: Finita
A46: Propiedad intelectual | B46: 11732 | C46: 14761 | D46: Finita
...

Sheet Segmentos
A1: SQM – Segmentos operativos y geografía
A2: Desglose por negocio y por área geográfica. Cifras en MUS$.
A4: Segmentos 2025 | H4: Segmentos 2024
A5: Segmento | B5: Ingresos | C5: Costo de ventas | D5: Ganancia bruta | E5: Ganancia neta | F5: Mix ventas | H5: Segmento | I5: Ingresos | J5: Costo de ventas | K5: Ganancia bruta | L5: Ganancia neta | M5: Mix ventas
A6: Nutrición vegetal de especialidad | B6: 982397 | C6: -837328 | D6: 145069 | E6: 145069 | F6: =B6/SUM($B$6:$B$11) -> 0.21467415 | H6: Nutrición vegetal de especialidad | I6: 941940 | J6: -775152 | K6: 166788 | L6: 166788 | M6: =I6/SUM($I$6:$I$11) -> 0.20799066
A7: Yodo y derivados | B7: 1042780 | C7: -481233 | D7: 561547 | E7: 561547 | F7: =B7/SUM($B$6:$B$11) -> 0.22786909 | H7: Yodo y derivados | I7: 968312 | J7: -444904 | K7: 523408 | L7: 523408 | M7: =I7/SUM($I$6:$I$11) -> 0.21381389
A8: Litio y derivados | B8: 2288245 | C8: -1684776 | D8: 603469 | E8: 603469 | F8: =B8/SUM($B$6:$B$11) -> 0.50002906 | H8: Litio y derivados | I8: 2241250 | J8: -1666328 | K8: 574922 | L8: 574922 | M8: =I8/SUM($I$6:$I$11) -> 0.49489253
A9: Químicos industriales | B9: 75402 | C9: -44810 | D9: 30592 | E9: 30592 | F9: =B9/SUM($B$6:$B$11) -> 0.016476903 | H9: Químicos industriales | I9: 78155 | J9: -47453 | K9: 30702 | L9: 30702 | M9: =I9/SUM($I$6:$I$11) -> 0.017257479
A10: Potasio | B10: 155507 | C10: -143340 | D10: 12167 | E10: 12167 | F10: =B10/SUM($B$6:$B$11) -> 0.03398151 | H10: Potasio | I10: 270783 | J10: -236390 | K10: 34393 | L10: 34393 | M10: =I10/SUM($I$6:$I$11) -> 0.05979185
A11: Otros productos y servicios | B11: 31893 | C11: -32137 | D11: -244 | E11: -244 | F11: =B11/SUM($B$6:$B$11) -> 0.006969283 | H11: Otros productos y servicios | I11: 28321 | J11: -31427 | K11: -3106 | L11: -3106 | M11: =I11/SUM($I$6:$I$11) -> 0.0062535868
A12: Total | B12: 4576224 | C12: -3223624 | D12: 1352600 | E12: 1352600 | F12: =B12/SUM($B$6:$B$11) -> 1 | H12: Total | I12: 4528761 | J12: -3201654 | K12: 1327107 | L12: 1327107 | M12: =I12/SUM($I$6:$I$11) -> 1
A15: Geografía 2025 | H15: Geografía 2024
A16: Región | B16: Ingresos | C16: Activos no corrientes | D16: Mix ingresos | H16: Región | I16: Ingresos | J16: Activos no corrientes | K16: Mix ingresos
A17: Chile | B17: 161510 | C17: 6344271 | D17: =B17/SUM($B$17:$B$21) -> 0.03529329 | H17: Chile | I17: 171551 | J17: 3654632 | K17: =I17/SUM($I$17:$I$21) -> 0.037880339
A18: Europa | B18: 188227 | C18: 8648 | D18: =B18/SUM($B$17:$B$21) -> 0.041131509 | H18: Europa | I18: 240629 | J18: 9022 | K18: =I18/SUM($I$17:$I$21) -> 0.053133517
A19: América Latina y Caribe | B19: 655019 | C19: 58962 | D19: =B19/SUM($B$17:$B$21) -> 0.14313526 | H19: América Latina y Caribe | I19: 681607 | J19: 34348 | K19: =I19/SUM($I$17:$I$21) -> 0.15050629
A20: América del Norte | B20: 689366 | C20: 44534 | D20: =B20/SUM($B$17:$B$21) -> 0.15064079 | H20: América del Norte | I20: 689794 | J20: 38543 | K20: =I20/SUM($I$17:$I$21) -> 0.15231407
A21: Asia y Otros | B21: 2882102 | C21: 1952968 | D21: =B21/SUM($B$17:$B$21) -> 0.62979915 | H21: Asia y Otros | I21: 2745180 | J21: 1900046 | K21: =I21/SUM($I$17:$I$21) -> 0.60616579
A22: Total | B22: 4576224 | C22: 8409383 | D22: =B22/SUM($B$17:$B$21) -> 1 | H22: Total | I22: 4528761 | J22: 5636591 | K22: =I22/SUM($I$17:$I$21) -> 1
